[2021-06-21 05:54:00,867] {taskinstance.py:876} INFO - Dependencies all met for <TaskInstance: orion.postInfo 2021-06-21T05:51:00+00:00 [queued]>
[2021-06-21 05:54:00,884] {taskinstance.py:876} INFO - Dependencies all met for <TaskInstance: orion.postInfo 2021-06-21T05:51:00+00:00 [queued]>
[2021-06-21 05:54:00,885] {taskinstance.py:1067} INFO - 
--------------------------------------------------------------------------------
[2021-06-21 05:54:00,886] {taskinstance.py:1068} INFO - Starting attempt 1 of 1
[2021-06-21 05:54:00,888] {taskinstance.py:1069} INFO - 
--------------------------------------------------------------------------------
[2021-06-21 05:54:00,896] {taskinstance.py:1087} INFO - Executing <Task(PythonOperator): postInfo> on 2021-06-21T05:51:00+00:00
[2021-06-21 05:54:00,904] {standard_task_runner.py:52} INFO - Started process 7368 to run task
[2021-06-21 05:54:00,906] {standard_task_runner.py:76} INFO - Running: ['***', 'tasks', 'run', 'orion', 'postInfo', '2021-06-21T05:51:00+00:00', '--job-id', '297', '--pool', 'default_pool', '--raw', '--subdir', 'DAGS_FOLDER/orion.py', '--cfg-path', '/tmp/tmp26u5b94g', '--error-file', '/tmp/tmphn1t_5m_']
[2021-06-21 05:54:00,907] {standard_task_runner.py:77} INFO - Job 297: Subtask postInfo
[2021-06-21 05:54:00,944] {logging_mixin.py:104} INFO - Running <TaskInstance: orion.postInfo 2021-06-21T05:51:00+00:00 [running]> on host 438558517cf9
[2021-06-21 05:54:00,995] {taskinstance.py:1282} INFO - Exporting the following env vars:
AIRFLOW_CTX_DAG_OWNER=***
AIRFLOW_CTX_DAG_ID=orion
AIRFLOW_CTX_TASK_ID=postInfo
AIRFLOW_CTX_EXECUTION_DATE=2021-06-21T05:51:00+00:00
AIRFLOW_CTX_DAG_RUN_ID=scheduled__2021-06-21T05:51:00+00:00
[2021-06-21 05:54:01,000] {taskinstance.py:1481} ERROR - Task failed with exception
Traceback (most recent call last):
  File "/home/airflow/.local/lib/python3.6/site-packages/urllib3/connection.py", line 160, in _new_conn
    (self._dns_host, self.port), self.timeout, **extra_kw
  File "/home/airflow/.local/lib/python3.6/site-packages/urllib3/util/connection.py", line 84, in create_connection
    raise err
  File "/home/airflow/.local/lib/python3.6/site-packages/urllib3/util/connection.py", line 74, in create_connection
    sock.connect(sa)
ConnectionRefusedError: [Errno 111] Connection refused

During handling of the above exception, another exception occurred:

Traceback (most recent call last):
  File "/home/airflow/.local/lib/python3.6/site-packages/urllib3/connectionpool.py", line 677, in urlopen
    chunked=chunked,
  File "/home/airflow/.local/lib/python3.6/site-packages/urllib3/connectionpool.py", line 392, in _make_request
    conn.request(method, url, **httplib_request_kw)
  File "/usr/local/lib/python3.6/http/client.py", line 1287, in request
    self._send_request(method, url, body, headers, encode_chunked)
  File "/usr/local/lib/python3.6/http/client.py", line 1333, in _send_request
    self.endheaders(body, encode_chunked=encode_chunked)
  File "/usr/local/lib/python3.6/http/client.py", line 1282, in endheaders
    self._send_output(message_body, encode_chunked=encode_chunked)
  File "/usr/local/lib/python3.6/http/client.py", line 1042, in _send_output
    self.send(msg)
  File "/usr/local/lib/python3.6/http/client.py", line 980, in send
    self.connect()
  File "/home/airflow/.local/lib/python3.6/site-packages/urllib3/connection.py", line 187, in connect
    conn = self._new_conn()
  File "/home/airflow/.local/lib/python3.6/site-packages/urllib3/connection.py", line 172, in _new_conn
    self, "Failed to establish a new connection: %s" % e
urllib3.exceptions.NewConnectionError: <urllib3.connection.HTTPConnection object at 0x7f9f59638dd8>: Failed to establish a new connection: [Errno 111] Connection refused

During handling of the above exception, another exception occurred:

Traceback (most recent call last):
  File "/home/airflow/.local/lib/python3.6/site-packages/requests/adapters.py", line 449, in send
    timeout=timeout
  File "/home/airflow/.local/lib/python3.6/site-packages/urllib3/connectionpool.py", line 727, in urlopen
    method, url, error=e, _pool=self, _stacktrace=sys.exc_info()[2]
  File "/home/airflow/.local/lib/python3.6/site-packages/urllib3/util/retry.py", line 446, in increment
    raise MaxRetryError(_pool, url, error or ResponseError(cause))
urllib3.exceptions.MaxRetryError: HTTPConnectionPool(host='172.19.0.5', port=1026): Max retries exceeded with url: /v2/entities/Street1 (Caused by NewConnectionError('<urllib3.connection.HTTPConnection object at 0x7f9f59638dd8>: Failed to establish a new connection: [Errno 111] Connection refused',))

During handling of the above exception, another exception occurred:

Traceback (most recent call last):
  File "/home/airflow/.local/lib/python3.6/site-packages/airflow/models/taskinstance.py", line 1137, in _run_raw_task
    self._prepare_and_execute_task_with_callbacks(context, task)
  File "/home/airflow/.local/lib/python3.6/site-packages/airflow/models/taskinstance.py", line 1311, in _prepare_and_execute_task_with_callbacks
    result = self._execute_task(context, task_copy)
  File "/home/airflow/.local/lib/python3.6/site-packages/airflow/models/taskinstance.py", line 1341, in _execute_task
    result = task_copy.execute(context=context)
  File "/home/airflow/.local/lib/python3.6/site-packages/airflow/operators/python.py", line 150, in execute
    return_value = self.execute_callable()
  File "/home/airflow/.local/lib/python3.6/site-packages/airflow/operators/python.py", line 161, in execute_callable
    return self.python_callable(*self.op_args, **self.op_kwargs)
  File "/opt/airflow/dags/orion.py", line 24, in postInfo
    info = requests.get(urlFiware).json()
  File "/home/airflow/.local/lib/python3.6/site-packages/requests/api.py", line 76, in get
    return request('get', url, params=params, **kwargs)
  File "/home/airflow/.local/lib/python3.6/site-packages/requests/api.py", line 61, in request
    return session.request(method=method, url=url, **kwargs)
  File "/home/airflow/.local/lib/python3.6/site-packages/requests/sessions.py", line 542, in request
    resp = self.send(prep, **send_kwargs)
  File "/home/airflow/.local/lib/python3.6/site-packages/requests/sessions.py", line 655, in send
    r = adapter.send(request, **kwargs)
  File "/home/airflow/.local/lib/python3.6/site-packages/requests/adapters.py", line 516, in send
    raise ConnectionError(e, request=request)
requests.exceptions.ConnectionError: HTTPConnectionPool(host='172.19.0.5', port=1026): Max retries exceeded with url: /v2/entities/Street1 (Caused by NewConnectionError('<urllib3.connection.HTTPConnection object at 0x7f9f59638dd8>: Failed to establish a new connection: [Errno 111] Connection refused',))
[2021-06-21 05:54:01,005] {taskinstance.py:1531} INFO - Marking task as FAILED. dag_id=orion, task_id=postInfo, execution_date=20210621T055100, start_date=20210621T055400, end_date=20210621T055401
[2021-06-21 05:54:01,038] {local_task_job.py:151} INFO - Task exited with return code 1
